Traceback (most recent call last):
  File "c:\users\user\appdata\local\programs\python\python39\lib\site-packages\jupyter_cache\executors\utils.py", line 51, in single_nb_execution
    executenb(
  File "c:\users\user\appdata\local\programs\python\python39\lib\site-packages\nbclient\client.py", line 1093, in execute
    return NotebookClient(nb=nb, resources=resources, km=km, **kwargs).execute()
  File "c:\users\user\appdata\local\programs\python\python39\lib\site-packages\nbclient\util.py", line 84, in wrapped
    return just_run(coro(*args, **kwargs))
  File "c:\users\user\appdata\local\programs\python\python39\lib\site-packages\nbclient\util.py", line 62, in just_run
    return loop.run_until_complete(coro)
  File "c:\users\user\appdata\local\programs\python\python39\lib\asyncio\base_events.py", line 642, in run_until_complete
    return future.result()
  File "c:\users\user\appdata\local\programs\python\python39\lib\site-packages\nbclient\client.py", line 559, in async_execute
    await self.async_execute_cell(
  File "c:\users\user\appdata\local\programs\python\python39\lib\site-packages\nbclient\client.py", line 854, in async_execute_cell
    self._check_raise_for_error(cell, exec_reply)
  File "c:\users\user\appdata\local\programs\python\python39\lib\site-packages\nbclient\client.py", line 756, in _check_raise_for_error
    raise CellExecutionError.from_cell_and_msg(cell, exec_reply_content)
nbclient.exceptions.CellExecutionError: An error occurred while executing the following cell:
------------------
indice=2
#indice=slice(3)

with tarfile.open(RAW_IMAGES_NAME) as f:
    m=f.getmembers()[indice]
    print(m)
    img=decode_image_from_raw_bytes(f.extractfile(m).read())
    print(img.shape)
------------------

[1;31m---------------------------------------------------------------------------[0m
[1;31mFileNotFoundError[0m                         Traceback (most recent call last)
[1;32m~\AppData\Local\Temp/ipykernel_16336/914438691.py[0m in [0;36m<module>[1;34m[0m
[0;32m      2[0m [1;31m#indice=slice(3)[0m[1;33m[0m[1;33m[0m[0m
[0;32m      3[0m [1;33m[0m[0m
[1;32m----> 4[1;33m [1;32mwith[0m [0mtarfile[0m[1;33m.[0m[0mopen[0m[1;33m([0m[0mRAW_IMAGES_NAME[0m[1;33m)[0m [1;32mas[0m [0mf[0m[1;33m:[0m[1;33m[0m[1;33m[0m[0m
[0m[0;32m      5[0m     [0mm[0m[1;33m=[0m[0mf[0m[1;33m.[0m[0mgetmembers[0m[1;33m([0m[1;33m)[0m[1;33m[[0m[0mindice[0m[1;33m][0m[1;33m[0m[1;33m[0m[0m
[0;32m      6[0m     [0mprint[0m[1;33m([0m[0mm[0m[1;33m)[0m[1;33m[0m[1;33m[0m[0m

[1;32mc:\users\user\appdata\local\programs\python\python39\lib\tarfile.py[0m in [0;36mopen[1;34m(cls, name, mode, fileobj, bufsize, **kwargs)[0m
[0;32m   1609[0m                     [0msaved_pos[0m [1;33m=[0m [0mfileobj[0m[1;33m.[0m[0mtell[0m[1;33m([0m[1;33m)[0m[1;33m[0m[1;33m[0m[0m
[0;32m   1610[0m                 [1;32mtry[0m[1;33m:[0m[1;33m[0m[1;33m[0m[0m
[1;32m-> 1611[1;33m                     [1;32mreturn[0m [0mfunc[0m[1;33m([0m[0mname[0m[1;33m,[0m [1;34m"r"[0m[1;33m,[0m [0mfileobj[0m[1;33m,[0m [1;33m**[0m[0mkwargs[0m[1;33m)[0m[1;33m[0m[1;33m[0m[0m
[0m[0;32m   1612[0m                 [1;32mexcept[0m [1;33m([0m[0mReadError[0m[1;33m,[0m [0mCompressionError[0m[1;33m)[0m[1;33m:[0m[1;33m[0m[1;33m[0m[0m
[0;32m   1613[0m                     [1;32mif[0m [0mfileobj[0m [1;32mis[0m [1;32mnot[0m [1;32mNone[0m[1;33m:[0m[1;33m[0m[1;33m[0m[0m

[1;32mc:\users\user\appdata\local\programs\python\python39\lib\tarfile.py[0m in [0;36mgzopen[1;34m(cls, name, mode, fileobj, compresslevel, **kwargs)[0m
[0;32m   1673[0m [1;33m[0m[0m
[0;32m   1674[0m         [1;32mtry[0m[1;33m:[0m[1;33m[0m[1;33m[0m[0m
[1;32m-> 1675[1;33m             [0mfileobj[0m [1;33m=[0m [0mGzipFile[0m[1;33m([0m[0mname[0m[1;33m,[0m [0mmode[0m [1;33m+[0m [1;34m"b"[0m[1;33m,[0m [0mcompresslevel[0m[1;33m,[0m [0mfileobj[0m[1;33m)[0m[1;33m[0m[1;33m[0m[0m
[0m[0;32m   1676[0m         [1;32mexcept[0m [0mOSError[0m[1;33m:[0m[1;33m[0m[1;33m[0m[0m
[0;32m   1677[0m             [1;32mif[0m [0mfileobj[0m [1;32mis[0m [1;32mnot[0m [1;32mNone[0m [1;32mand[0m [0mmode[0m [1;33m==[0m [1;34m'r'[0m[1;33m:[0m[1;33m[0m[1;33m[0m[0m

[1;32mc:\users\user\appdata\local\programs\python\python39\lib\gzip.py[0m in [0;36m__init__[1;34m(self, filename, mode, compresslevel, fileobj, mtime)[0m
[0;32m    171[0m             [0mmode[0m [1;33m+=[0m [1;34m'b'[0m[1;33m[0m[1;33m[0m[0m
[0;32m    172[0m         [1;32mif[0m [0mfileobj[0m [1;32mis[0m [1;32mNone[0m[1;33m:[0m[1;33m[0m[1;33m[0m[0m
[1;32m--> 173[1;33m             [0mfileobj[0m [1;33m=[0m [0mself[0m[1;33m.[0m[0mmyfileobj[0m [1;33m=[0m [0mbuiltins[0m[1;33m.[0m[0mopen[0m[1;33m([0m[0mfilename[0m[1;33m,[0m [0mmode[0m [1;32mor[0m [1;34m'rb'[0m[1;33m)[0m[1;33m[0m[1;33m[0m[0m
[0m[0;32m    174[0m         [1;32mif[0m [0mfilename[0m [1;32mis[0m [1;32mNone[0m[1;33m:[0m[1;33m[0m[1;33m[0m[0m
[0;32m    175[0m             [0mfilename[0m [1;33m=[0m [0mgetattr[0m[1;33m([0m[0mfileobj[0m[1;33m,[0m [1;34m'name'[0m[1;33m,[0m [1;34m''[0m[1;33m)[0m[1;33m[0m[1;33m[0m[0m

[1;31mFileNotFoundError[0m: [Errno 2] No such file or directory: '../Data/lfw.tgz'
FileNotFoundError: [Errno 2] No such file or directory: '../Data/lfw.tgz'

