Traceback (most recent call last):
  File "/opt/hostedtoolcache/Python/3.7.13/x64/lib/python3.7/site-packages/jupyter_cache/executors/utils.py", line 56, in single_nb_execution
    record_timing=False,
  File "/opt/hostedtoolcache/Python/3.7.13/x64/lib/python3.7/site-packages/nbclient/client.py", line 1204, in execute
    return NotebookClient(nb=nb, resources=resources, km=km, **kwargs).execute()
  File "/opt/hostedtoolcache/Python/3.7.13/x64/lib/python3.7/site-packages/nbclient/util.py", line 84, in wrapped
    return just_run(coro(*args, **kwargs))
  File "/opt/hostedtoolcache/Python/3.7.13/x64/lib/python3.7/site-packages/nbclient/util.py", line 62, in just_run
    return loop.run_until_complete(coro)
  File "/opt/hostedtoolcache/Python/3.7.13/x64/lib/python3.7/asyncio/base_events.py", line 587, in run_until_complete
    return future.result()
  File "/opt/hostedtoolcache/Python/3.7.13/x64/lib/python3.7/site-packages/nbclient/client.py", line 664, in async_execute
    cell, index, execution_count=self.code_cells_executed + 1
  File "/opt/hostedtoolcache/Python/3.7.13/x64/lib/python3.7/site-packages/nbclient/client.py", line 965, in async_execute_cell
    await self._check_raise_for_error(cell, cell_index, exec_reply)
  File "/opt/hostedtoolcache/Python/3.7.13/x64/lib/python3.7/site-packages/nbclient/client.py", line 862, in _check_raise_for_error
    raise CellExecutionError.from_cell_and_msg(cell, exec_reply_content)
nbclient.exceptions.CellExecutionError: An error occurred while executing the following cell:
------------------
# usando el m√©todo de clase
path = 'https://raw.githubusercontent.com/AprendizajeProfundo/Libro_Fundamentos_Programacion/main/Python/Datos/cuenta.csv'
mi_cuenta = CuentaBancaria.from_csv(path)
print(mi_cuenta.cliente, mi_cuenta.numero_cuenta, mi_cuenta.saldo, mi_cuenta.creada_en)
------------------

[0;31m---------------------------------------------------------------------------[0m
[0;31mFileNotFoundError[0m                         Traceback (most recent call last)
[0;32m/tmp/ipykernel_2477/1779118915.py[0m in [0;36m<module>[0;34m[0m
[1;32m      1[0m [0;31m# usando el m√©todo de clase[0m[0;34m[0m[0;34m[0m[0;34m[0m[0m
[1;32m      2[0m [0mpath[0m [0;34m=[0m [0;34m'https://raw.githubusercontent.com/AprendizajeProfundo/Libro_Fundamentos_Programacion/main/Python/Datos/cuenta.csv'[0m[0;34m[0m[0;34m[0m[0m
[0;32m----> 3[0;31m [0mmi_cuenta[0m [0;34m=[0m [0mCuentaBancaria[0m[0;34m.[0m[0mfrom_csv[0m[0;34m([0m[0mpath[0m[0;34m)[0m[0;34m[0m[0;34m[0m[0m
[0m[1;32m      4[0m [0mprint[0m[0;34m([0m[0mmi_cuenta[0m[0;34m.[0m[0mcliente[0m[0;34m,[0m [0mmi_cuenta[0m[0;34m.[0m[0mnumero_cuenta[0m[0;34m,[0m [0mmi_cuenta[0m[0;34m.[0m[0msaldo[0m[0;34m,[0m [0mmi_cuenta[0m[0;34m.[0m[0mcreada_en[0m[0;34m)[0m[0;34m[0m[0;34m[0m[0m

[0;32m/tmp/ipykernel_2477/1014366421.py[0m in [0;36mfrom_csv[0;34m(cls, filepath)[0m
[1;32m     17[0m     [0;34m@[0m[0mclassmethod[0m[0;34m[0m[0;34m[0m[0m
[1;32m     18[0m     [0;32mdef[0m [0mfrom_csv[0m[0;34m([0m[0mcls[0m[0;34m,[0m [0mfilepath[0m[0;34m)[0m[0;34m:[0m[0;34m[0m[0;34m[0m[0m
[0;32m---> 19[0;31m         [0;32mwith[0m [0mopen[0m[0;34m([0m[0mfilepath[0m[0;34m,[0m [0;34m"r"[0m[0;34m)[0m [0;32mas[0m [0mf[0m[0;34m:[0m[0;34m[0m[0;34m[0m[0m
[0m[1;32m     20[0m             [0mfila[0m [0;34m=[0m [0mcsv[0m[0;34m.[0m[0mreader[0m[0;34m([0m[0mf[0m[0;34m)[0m[0;34m.[0m[0m__next__[0m[0;34m([0m[0;34m)[0m[0;34m[0m[0;34m[0m[0m
[1;32m     21[0m             [0mcliente[0m[0;34m,[0m [0mnumero_cuenta[0m [0;34m=[0m [0mfila[0m[0;34m[0m[0;34m[0m[0m

[0;31mFileNotFoundError[0m: [Errno 2] No such file or directory: 'https://raw.githubusercontent.com/AprendizajeProfundo/Libro_Fundamentos_Programacion/main/Python/Datos/cuenta.csv'
FileNotFoundError: [Errno 2] No such file or directory: 'https://raw.githubusercontent.com/AprendizajeProfundo/Libro_Fundamentos_Programacion/main/Python/Datos/cuenta.csv'

